Traceback (most recent call last):
  File "/home/user/.virtualenvs/fine-tuning/lib/python3.9/site-packages/nbclient/client.py", line 730, in _async_poll_for_reply
    msg = await ensure_async(self.kc.shell_channel.get_msg(timeout=new_timeout))
  File "/home/user/.virtualenvs/fine-tuning/lib/python3.9/site-packages/nbclient/util.py", line 96, in ensure_async
    result = await obj
  File "/home/user/.virtualenvs/fine-tuning/lib/python3.9/site-packages/jupyter_client/channels.py", line 230, in get_msg
    raise Empty
_queue.Empty

During handling of the above exception, another exception occurred:

Traceback (most recent call last):
  File "/home/user/.virtualenvs/fine-tuning/lib/python3.9/site-packages/jupyter_cache/executors/utils.py", line 51, in single_nb_execution
    executenb(
  File "/home/user/.virtualenvs/fine-tuning/lib/python3.9/site-packages/nbclient/client.py", line 1204, in execute
    return NotebookClient(nb=nb, resources=resources, km=km, **kwargs).execute()
  File "/home/user/.virtualenvs/fine-tuning/lib/python3.9/site-packages/nbclient/util.py", line 84, in wrapped
    return just_run(coro(*args, **kwargs))
  File "/home/user/.virtualenvs/fine-tuning/lib/python3.9/site-packages/nbclient/util.py", line 62, in just_run
    return loop.run_until_complete(coro)
  File "/usr/lib/python3.9/asyncio/base_events.py", line 642, in run_until_complete
    return future.result()
  File "/home/user/.virtualenvs/fine-tuning/lib/python3.9/site-packages/nbclient/client.py", line 663, in async_execute
    await self.async_execute_cell(
  File "/home/user/.virtualenvs/fine-tuning/lib/python3.9/site-packages/nbclient/client.py", line 949, in async_execute_cell
    exec_reply = await self.task_poll_for_reply
  File "/home/user/.virtualenvs/fine-tuning/lib/python3.9/site-packages/nbclient/client.py", line 754, in _async_poll_for_reply
    await self._async_handle_timeout(timeout, cell)
  File "/home/user/.virtualenvs/fine-tuning/lib/python3.9/site-packages/nbclient/client.py", line 801, in _async_handle_timeout
    raise CellTimeoutError.error_from_timeout_and_cell(
nbclient.exceptions.CellTimeoutError: A cell timed out while it was being executed, after 30 seconds.
The message was: Cell execution timed out.
Here is a preview of the cell contents:
-------------------
['from pathlib import Path', 'from plots import show_metrics_plot_different_scales', '', 'ylim = (-0.02, 1.02)', 'metrics_loss = dict(']
...
['metrics_list = [metrics_loss, metrics_accuracy]', "results = pd.read_feather('_data/results.short_run.lr2e-5.feather')", 'title = fr"Metrics: Fine-Tuning {CHECKPOINT} at $\\alpha=2e^{-5}$"', 'show_metrics_plot_different_scales(results, metrics_list, n_rows, n_cols, by=BY, suptitle=title, label="Scaled Metrics", ', "                                   scale=(plot_scale, plot_scale * 2), legend_adj=(0.992, 1.025), image_file='_images/results.short_run.lr2e-5.png')"]
-------------------

